//! # Exercise
//!
//! Fill out the missing details in `telemetry_wrapper` to capture the information we just discussed.

use std::error::Error;
use std::fmt::{Debug, Write};
use std::fmt::{Display, Formatter};
use std::io::ErrorKind;
use tracing::field::Empty;

mod subscriber;

/// Another interesting question when it comes to errors: who should log them?
///
/// The answer depends on what you care about and the facilities available to you.
/// In an API, my recommendation is to have a top-level middleware which takes care of logging
/// all "fatal" errorsâ€”i.e. errors that will be converted directly into an error HTTP response for
/// your caller.
///
/// This `telemetry_wrapper` function is meant to play such a role: it wraps the underlying
/// computation and takes care of logging any errors that arise from it.
#[tracing::instrument(
    "my_task", 
    // The precise naming choice here is not important, it's likely to be determined by
    // the conventions and constraints of your team/org. 
    // What matters is capturing the enough information!
    fields(error.msg = Empty, error.debug = Empty, error.source_chain = Empty)
)]
fn telemetry_wrapper() -> Result<(), OpaqueError> {
    let outcome = fallible_operation();
    if let Err(e) = &outcome {
        // Check out the methods in the `tracing::field` module!
        todo!()
    }
    outcome
}

/// Return a string representation of the source chain of the given error.
fn source_chain<E>(e: E) -> String
where
    E: Error,
{
    let mut result = String::new();
    let mut source = e.source();
    while let Some(e) = source {
        // We use the debug representation here to maximise the amount of information we capture
        // about errors in the chain.
        writeln!(&mut result, "{:?}", e).unwrap();
        source = e.source();
    }
    result
}

fn fallible_operation() -> Result<(), OpaqueError> {
    let root_error = std::io::Error::new(
        ErrorKind::ConnectionRefused,
        "Failed to connect to 127.0.0.1:4236",
    );
    let intermediate_error = DatabaseError {
        source: root_error,
        query: "SELECT * FROM table",
    };
    Err(OpaqueError {
        source: intermediate_error,
    })
}

struct DatabaseError {
    source: std::io::Error,
    query: &'static str,
}

impl Debug for DatabaseError {
    fn fmt(&self, f: &mut Formatter<'_>) -> std::fmt::Result {
        write!(f, "Failed to execute: `{}`", self.query)
    }
}

impl Display for DatabaseError {
    fn fmt(&self, f: &mut Formatter<'_>) -> std::fmt::Result {
        write!(f, "Failed to execute a database query")
    }
}

impl Error for DatabaseError {
    fn source(&self) -> Option<&(dyn Error + 'static)> {
        Some(&self.source)
    }
}

#[derive(Debug)]
struct OpaqueError {
    source: DatabaseError,
}

impl Display for OpaqueError {
    fn fmt(&self, f: &mut Formatter<'_>) -> std::fmt::Result {
        // This is our top-level error and we don't talk about databases with our end users,
        // it's an implementation detail of the system.
        write!(
            f,
            "The service is temporarily unavailable, please try again later"
        )
    }
}

impl Error for OpaqueError {
    fn source(&self) -> Option<&(dyn Error + 'static)> {
        Some(&self.source)
    }
}

#[cfg(test)]
mod tests {
    use super::telemetry_wrapper;
    use crate::subscriber::init_test_subscriber;

    #[test]
    fn error_span() {
        let logging_buffer = init_test_subscriber();

        let error = telemetry_wrapper().unwrap_err();

        // Check that the log output matches what we expect.
        let logging_output = logging_buffer.log_output().unwrap();
        let logging_output = logging_output.text();

        assert!(
            logging_output.contains(
                "error.msg=The service is temporarily unavailable, please try again later"
            ),
            "The logging output is missing the expected error.msg:\n{}",
            logging_output
        );
        // Depending on how each error type implements `Debug` and `Display`, we might get
        // different levels of overlap between `error.debug` and `error.source_chain`.
        assert!(
            logging_output.contains(
                r#"error.debug=OpaqueError { source: Failed to execute: `SELECT * FROM table` }"#
            ),
            "The logging output is missing the expected error.debug:\n{}",
            logging_output
        );
        assert!(logging_output.contains(r#"error.source_chain="Failed to execute: `SELECT * FROM table`\nCustom { kind: ConnectionRefused, error: \"Failed to connect to 127.0.0.1:4236\" }"#),
            "The logging output is missing the expected error.source_chain:\n{}",
            logging_output
        );
    }
}
